Workbook
Name Dept: #REF!
Name Team: #REF!

Sheet Dashboard
B2: Course No.4: Business Japanese Speaking Class performance Assessment & Attendance Report
B3: Period : [28th Dec ~ 15th Mar 2026] with 30 Hours-20 Sessions
B5: By Level | D5: No. of Members | E5: Attendance Report By Department | G5: >65%~<=100% Good | H5: >50%~ <=65% Fair | I5: >10%~<=50% Poor | J5: TOTAL
B6: Group1: N2 & N3 | D6: 9 | E6: Offshore Development Department -1 | G6: =COUNTIFS(F26:F45,E6, H26:H45,">65%",H26:H45,"<=100%") -> 8 | H6: =COUNTIFS(F26:F45,E6, H26:H45,">50%",H26:H45,"<=65%") -> 1 | I6: =COUNTIFS(F26:F45,E6, H26:H45,">10%",H26:H45,"<=50%") -> 0 | J6: =SUM(G6:I6) -> 9
B7: Group2: N4 & N5 | D7: 11 | E7: Offshore Development Department -2 | G7: =COUNTIFS(F26:F45,E7, H26:H45,">65%",H26:H45,"<=100%") -> 10 | H7: =COUNTIFS(F26:F45,E7, H26:H45,">50%",H26:H45,"<=65%") -> 1 | I7: =COUNTIFS(F26:F45,E7, H26:H45,">10%",H26:H45,"<=50%") -> 0 | J7: =SUM(G7:I7) -> 11
B8: TOTAL | D8: =SUM(D6:D7) -> 20 | G8: =SUM(G6:G7) -> 18 | H8: =SUM(H6:H7) -> 2 | I8: =SUM(I6:I7) -> 0 | J8: =SUM(G8:I8) -> 20
B10: 1. Participants Self-Assessment Score | I10: =AB25 -> Any Improvement Comment/Suggestion (Optional)
B11: Title & Contents | E11: Offshore Department -1 | G11: Offshore Department -2 | H11: Average Score
B12: =P25 -> Business Conversation Fluency (1-5)
B13: =Q25 -> Daily Business Expressions (Ho-Ren-So) (1–5)
B14: =R25 -> Politeness & Keigo Usage (1-5)
B15: =S25 -> Listening Comprehension (1-5)
B16: =T25 -> Communicati Speaking & Role-play (1–5)
B17: =U25 -> Email & Written Communication (1–5)
B18: =V25 -> Vocabulary & Terminology (1–5)
B19: =W25 -> Response & Communication Clarity (1–5)
B20: =X25 -> Understanding Instructions & Tasks (1–5)
B21: =Y25 -> Before Session Score (1-5)
B22: =Z25 -> After Session Score (1-5)
B23: =AB25 -> Any Improvement Comment/Suggestion (Optional)
P24: *** Please fill your rating from P to AB columns. | AC24: AC and AD are PMO analysis Columns
B25: Sr. No. | C25: Name | D25: Group | E25: JLPT Study Level | F25: Department | G25: Team | H25: Attendent % | I25: Leave Days | J25: Late Days | K25: Absent Days | L25: Attendent Days | M25: Attendance % Range | N25: Attendance Status | O25: No. of Classes/Timetable | P25: Business Conversation Fluency (1-5) | Q25: Daily Business Expressions (Ho-Ren-So) (1–5) | R25: Politeness & Keigo Usage (1-5) | S25: Listening Comprehension (1-5) | T25: Communicati Speaking & Role-play (1–5) | U25: Email & Written Communication (1–5) | V25: Vocabulary & Terminology (1–5) | W25: Response & Communication Clarity (1–5) | X25: Understanding Instructions & Tasks (1–5) | Y25: Before Session Score (1-5) | Z25: After Session Score (1-5) | AA25: Recommend next Batch for DAT's Growth (1-5) | AB25: Any Improvement Comment/Suggestion (Optional) | AC25: Average Scoring (1-5) | AD25: NGLP Japanese Speaking Readiness Score (1-5)
B26: 1 | C26: Yin Pa Pa | D26: Group1 | E26: =VLOOKUP(C26,Attendance!D13:M33,10, FALSE) -> N3 | F26: Offshore Development Department -1 | G26: MARK/SMART | H26: =VLOOKUP(C26,Attendance!D13:F33,3, FALSE) -> 1 | I26: =VLOOKUP(C26,Attendance!D13:H33,5, FALSE) -> 0 | J26: =VLOOKUP(C26,Attendance!D13:K33,6, FALSE) -> 0 | K26: =VLOOKUP(C26,Attendance!D13:K33,7, FALSE) -> 0 | L26: =VLOOKUP(C26,Attendance!D13:K33,8, FALSE) -> 20 | M26: =IF(H26>65%, ">65%~<=100%", IF(H26>50%, ">50%~<=65%", IF(H26>10%, ">10%~<=50%", "<=10%"))) -> >65%~<=100% | N26: =IF(AND(H26>65%, H26<=1), "Good", IF(AND(H26>50%, H26<=65%), "Fair", IF(AND(H26>10%, H26<=50%), "Poor", IF(H26<=10%, "Critical", "Out of range")))) -> Good | O26: Sat, Sun 19:00-20:30 (3hrs per week) ==> 1.5 Hrs per day * 15 Days = 30 Hours Course 28th Jan ~ 15th Mar 2026 via Online | AC26: =IF(COUNT(P26:Z26)=0,"",ROUND(AVERAGE(P26:Z26),2)) | AD26: =IF(AC26="","",IF(AC26>=4.2,"High Ready (4.2–5.0)",IF(AC26>=3.5,"Ready (3.5–4.1)","Developing (≤3.4)")))
B27: 2 | C27: Nyein Aye Mon | D27: Group1 | E27: =VLOOKUP(C27,Attendance!D14:M34,10, FALSE) -> N3 | F27: Offshore Development Department -1 | G27: DBP | H27: =VLOOKUP(C27,Attendance!D14:F34,3, FALSE) -> 0.8 | I27: =VLOOKUP(C27,Attendance!D14:H34,5, FALSE) -> 4 | J27: =VLOOKUP(C27,Attendance!D14:K34,6, FALSE) -> 0 | K27: =VLOOKUP(C27,Attendance!D14:K34,7, FALSE) -> 0 | L27: =VLOOKUP(C27,Attendance!D14:K34,8, FALSE) -> 16 | M27: =IF(H27>65%, ">65%~<=100%", IF(H27>50%, ">50%~<=65%", IF(H27>10%, ">10%~<=50%", "<=10%"))) -> >65%~<=100% | N27: =IF(AND(H27>65%, H27<=1), "Good", IF(AND(H27>50%, H27<=65%), "Fair", IF(AND(H27>10%, H27<=50%), "Poor", IF(H27<=10%, "Critical", "Out of range")))) -> Good | AC27: =IF(COUNT(P27:Z27)=0,"",ROUND(AVERAGE(P27:Z27),2)) | AD27: =IF(AC27="","",IF(AC27>=4.2,"High Ready (4.2–5.0)",IF(AC27>=3.5,"Ready (3.5–4.1)","Developing (≤3.4)")))
B28: 3 | C28: Nwe Oo Mon | D28: Group1 | E28: =VLOOKUP(C28,Attendance!D15:M35,10, FALSE) -> N2 | F28: Offshore Development Department -2 | G28: WEB | H28: =VLOOKUP(C28,Attendance!D15:F35,3, FALSE) -> 0.95 | I28: =VLOOKUP(C28,Attendance!D15:H35,5, FALSE) -> 1 | J28: =VLOOKUP(C28,Attendance!D15:K35,6, FALSE) -> 0 | K28: =VLOOKUP(C28,Attendance!D15:K35,7, FALSE) -> 0 | L28: =VLOOKUP(C28,Attendance!D15:K35,8, FALSE) -> 19 | M28: =IF(H28>65%, ">65%~<=100%", IF(H28>50%, ">50%~<=65%", IF(H28>10%, ">10%~<=50%", "<=10%"))) -> >65%~<=100% | N28: =IF(AND(H28>65%, H28<=1), "Good", IF(AND(H28>50%, H28<=65%), "Fair", IF(AND(H28>10%, H28<=50%), "Poor", IF(H28<=10%, "Critical", "Out of range")))) -> Good | AC28: =IF(COUNT(P28:Z28)=0,"",ROUND(AVERAGE(P28:Z28),2)) | AD28: =IF(AC28="","",IF(AC28>=4.2,"High Ready (4.2–5.0)",IF(AC28>=3.5,"Ready (3.5–4.1)","Developing (≤3.4)")))
B29: 4 | C29: YiMon Theint | D29: Group1 | E29: =VLOOKUP(C29,Attendance!D16:M36,10, FALSE) -> N3 | F29: Offshore Development Department -2 | G29: WEB | H29: =VLOOKUP(C29,Attendance!D16:F36,3, FALSE) -> 0.95 | I29: =VLOOKUP(C29,Attendance!D16:H36,5, FALSE) -> 1 | J29: =VLOOKUP(C29,Attendance!D16:K36,6, FALSE) -> 0 | K29: =VLOOKUP(C29,Attendance!D16:K36,7, FALSE) -> 0 | L29: =VLOOKUP(C29,Attendance!D16:K36,8, FALSE) -> 19 | M29: =IF(H29>65%, ">65%~<=100%", IF(H29>50%, ">50%~<=65%", IF(H29>10%, ">10%~<=50%", "<=10%"))) -> >65%~<=100% | N29: =IF(AND(H29>65%, H29<=1), "Good", IF(AND(H29>50%, H29<=65%), "Fair", IF(AND(H29>10%, H29<=50%), "Poor", IF(H29<=10%, "Critical", "Out of range")))) -> Good | AC29: =IF(COUNT(P29:Z29)=0,"",ROUND(AVERAGE(P29:Z29),2)) | AD29: =IF(AC29="","",IF(AC29>=4.2,"High Ready (4.2–5.0)",IF(AC29>=3.5,"Ready (3.5–4.1)","Developing (≤3.4)")))
B30: 5 | C30: Htar Htar Nwe | D30: Group1 | E30: =VLOOKUP(C30,Attendance!D17:M37,10, FALSE) -> N3 | F30: Offshore Development Department -2 | G30: SONAR-FR | H30: =VLOOKUP(C30,Attendance!D17:F37,3, FALSE) -> 0.8 | I30: =VLOOKUP(C30,Attendance!D17:H37,5, FALSE) -> 4 | J30: =VLOOKUP(C30,Attendance!D17:K37,6, FALSE) -> 0 | K30: =VLOOKUP(C30,Attendance!D17:K37,7, FALSE) -> 0 | L30: =VLOOKUP(C30,Attendance!D17:K37,8, FALSE) -> 16 | M30: =IF(H30>65%, ">65%~<=100%", IF(H30>50%, ">50%~<=65%", IF(H30>10%, ">10%~<=50%", "<=10%"))) -> >65%~<=100% | N30: =IF(AND(H30>65%, H30<=1), "Good", IF(AND(H30>50%, H30<=65%), "Fair", IF(AND(H30>10%, H30<=50%), "Poor", IF(H30<=10%, "Critical", "Out of range")))) -> Good | AC30: =IF(COUNT(P30:Z30)=0,"",ROUND(AVERAGE(P30:Z30),2)) | AD30: =IF(AC30="","",IF(AC30>=4.2,"High Ready (4.2–5.0)",IF(AC30>=3.5,"Ready (3.5–4.1)","Developing (≤3.4)")))
B31: 6 | C31: Win Thiri Han | D31: Group1 | E31: =VLOOKUP(C31,Attendance!D18:M38,10, FALSE) -> N3 | F31: Offshore Development Department -2 | G31: OSS | H31: =VLOOKUP(C31,Attendance!D18:F38,3, FALSE) -> 0.55 | I31: =VLOOKUP(C31,Attendance!D18:H38,5, FALSE) -> 9 | J31: =VLOOKUP(C31,Attendance!D18:K38,6, FALSE) -> 0 | K31: =VLOOKUP(C31,Attendance!D18:K38,7, FALSE) -> 0 | L31: =VLOOKUP(C31,Attendance!D18:K38,8, FALSE) -> 11 | M31: =IF(H31>65%, ">65%~<=100%", IF(H31>50%, ">50%~<=65%", IF(H31>10%, ">10%~<=50%", "<=10%"))) -> >50%~<=65% | N31: =IF(AND(H31>65%, H31<=1), "Good", IF(AND(H31>50%, H31<=65%), "Fair", IF(AND(H31>10%, H31<=50%), "Poor", IF(H31<=10%, "Critical", "Out of range")))) -> Fair | AC31: =IF(COUNT(P31:Z31)=0,"",ROUND(AVERAGE(P31:Z31),2)) | AD31: =IF(AC31="","",IF(AC31>=4.2,"High Ready (4.2–5.0)",IF(AC31>=3.5,"Ready (3.5–4.1)","Developing (≤3.4)")))
B32: 7 | C32: May Thazin Oo-2 | D32: Group1 | E32: =VLOOKUP(C32,Attendance!D19:M39,10, FALSE) -> N3 | F32: Offshore Development Department -2 | G32: KOSMO-Network21 | H32: =VLOOKUP(C32,Attendance!D19:F39,3, FALSE) -> 0.95 | I32: =VLOOKUP(C32,Attendance!D19:H39,5, FALSE) -> 0 | J32: =VLOOKUP(C32,Attendance!D19:K39,6, FALSE) -> 0 | K32: =VLOOKUP(C32,Attendance!D19:K39,7, FALSE) -> 1 | L32: =VLOOKUP(C32,Attendance!D19:K39,8, FALSE) -> 19 | M32: =IF(H32>65%, ">65%~<=100%", IF(H32>50%, ">50%~<=65%", IF(H32>10%, ">10%~<=50%", "<=10%"))) -> >65%~<=100% | N32: =IF(AND(H32>65%, H32<=1), "Good", IF(AND(H32>50%, H32<=65%), "Fair", IF(AND(H32>10%, H32<=50%), "Poor", IF(H32<=10%, "Critical", "Out of range")))) -> Good | AC32: =IF(COUNT(P32:Z32)=0,"",ROUND(AVERAGE(P32:Z32),2)) | AD32: =IF(AC32="","",IF(AC32>=4.2,"High Ready (4.2–5.0)",IF(AC32>=3.5,"Ready (3.5–4.1)","Developing (≤3.4)")))
B33: 8 | C33: Soe Nandar | D33: Group1 | E33: =VLOOKUP(C33,Attendance!D20:M40,10, FALSE) -> N2 | F33: Offshore Development Department -2 | G33: KOSMO-Network21 | H33: =VLOOKUP(C33,Attendance!D20:F40,3, FALSE) -> 0.95 | I33: =VLOOKUP(C33,Attendance!D20:H40,5, FALSE) -> 0 | J33: =VLOOKUP(C33,Attendance!D20:K40,6, FALSE) -> 0 | K33: =VLOOKUP(C33,Attendance!D20:K40,7, FALSE) -> 1 | L33: =VLOOKUP(C33,Attendance!D20:K40,8, FALSE) -> 19 | M33: =IF(H33>65%, ">65%~<=100%", IF(H33>50%, ">50%~<=65%", IF(H33>10%, ">10%~<=50%", "<=10%"))) -> >65%~<=100% | N33: =IF(AND(H33>65%, H33<=1), "Good", IF(AND(H33>50%, H33<=65%), "Fair", IF(AND(H33>10%, H33<=50%), "Poor", IF(H33<=10%, "Critical", "Out of range")))) -> Good | AC33: =IF(COUNT(P33:Z33)=0,"",ROUND(AVERAGE(P33:Z33),2)) | AD33: =IF(AC33="","",IF(AC33>=4.2,"High Ready (4.2–5.0)",IF(AC33>=3.5,"Ready (3.5–4.1)","Developing (≤3.4)")))
B34: 9 | C34: Hsu Nandar Htet | D34: Group1 | E34: =VLOOKUP(C34,Attendance!D21:M41,10, FALSE) -> N2 | F34: Offshore Development Department -1 | G34: FPD | H34: =VLOOKUP(C34,Attendance!D21:F41,3, FALSE) -> 0.6 | I34: =VLOOKUP(C34,Attendance!D21:H41,5, FALSE) -> 4 | J34: =VLOOKUP(C34,Attendance!D21:K41,6, FALSE) -> 0 | K34: =VLOOKUP(C34,Attendance!D21:K41,7, FALSE) -> 4 | L34: =VLOOKUP(C34,Attendance!D21:K41,8, FALSE) -> 12 | M34: =IF(H34>65%, ">65%~<=100%", IF(H34>50%, ">50%~<=65%", IF(H34>10%, ">10%~<=50%", "<=10%"))) -> >50%~<=65% | N34: =IF(AND(H34>65%, H34<=1), "Good", IF(AND(H34>50%, H34<=65%), "Fair", IF(AND(H34>10%, H34<=50%), "Poor", IF(H34<=10%, "Critical", "Out of range")))) -> Fair | O34: Sat, Sun 19:00-20:30 (3hrs per week) ==> 1.5 Hrs per day * 15 Days = 30 Hours Course 28th Jan ~ 15th Mar 2026 via Online | AC34: =IF(COUNT(P34:Z34)=0,"",ROUND(AVERAGE(P34:Z34),2)) | AD34: =IF(AC34="","",IF(AC34>=4.2,"High Ready (4.2–5.0)",IF(AC34>=3.5,"Ready (3.5–4.1)","Developing (≤3.4)")))
B35: 10 | C35: Saung Thinzar Khaing | D35: Group2 | E35: =VLOOKUP(C35,Attendance!D22:M42,10, FALSE) -> N5 | F35: Offshore Development Department -1 | G35: MARK/SMART | H35: =VLOOKUP(C35,Attendance!D22:F42,3, FALSE) -> 0.9 | I35: =VLOOKUP(C35,Attendance!D22:H42,5, FALSE) -> 1 | J35: =VLOOKUP(C35,Attendance!D22:K42,6, FALSE) -> 1 | K35: =VLOOKUP(C35,Attendance!D22:K42,7, FALSE) -> 1 | L35: =VLOOKUP(C35,Attendance!D22:K42,8, FALSE) -> 17 | M35: =IF(H35>65%, ">65%~<=100%", IF(H35>50%, ">50%~<=65%", IF(H35>10%, ">10%~<=50%", "<=10%"))) -> >65%~<=100% | N35: =IF(AND(H35>65%, H35<=1), "Good", IF(AND(H35>50%, H35<=65%), "Fair", IF(AND(H35>10%, H35<=50%), "Poor", IF(H35<=10%, "Critical", "Out of range")))) -> Good | AC35: =IF(COUNT(P35:Z35)=0,"",ROUND(AVERAGE(P35:Z35),2)) | AD35: =IF(AC35="","",IF(AC35>=4.2,"High Ready (4.2–5.0)",IF(AC35>=3.5,"Ready (3.5–4.1)","Developing (≤3.4)")))
B36: 11 | C36: Kyipyar Lwin | D36: Group2 | E36: =VLOOKUP(C36,Attendance!D23:M43,10, FALSE) -> N4 | F36: Offshore Development Department -1 | G36: SNR、MF | H36: =VLOOKUP(C36,Attendance!D23:F43,3, FALSE) -> 0.95 | I36: =VLOOKUP(C36,Attendance!D23:H43,5, FALSE) -> 1 | J36: =VLOOKUP(C36,Attendance!D23:K43,6, FALSE) -> 0 | K36: =VLOOKUP(C36,Attendance!D23:K43,7, FALSE) -> 0 | L36: =VLOOKUP(C36,Attendance!D23:K43,8, FALSE) -> 19 | M36: =IF(H36>65%, ">65%~<=100%", IF(H36>50%, ">50%~<=65%", IF(H36>10%, ">10%~<=50%", "<=10%"))) -> >65%~<=100% | N36: =IF(AND(H36>65%, H36<=1), "Good", IF(AND(H36>50%, H36<=65%), "Fair", IF(AND(H36>10%, H36<=50%), "Poor", IF(H36<=10%, "Critical", "Out of range")))) -> Good | AC36: =IF(COUNT(P36:Z36)=0,"",ROUND(AVERAGE(P36:Z36),2)) | AD36: =IF(AC36="","",IF(AC36>=4.2,"High Ready (4.2–5.0)",IF(AC36>=3.5,"Ready (3.5–4.1)","Developing (≤3.4)")))
B37: 12 | C37: Myo Soe Aung | D37: Group2 | E37: =VLOOKUP(C37,Attendance!D24:M44,10, FALSE) -> N5 | F37: Offshore Development Department -1 | G37: MARK/SMART | H37: =VLOOKUP(C37,Attendance!D24:F44,3, FALSE) -> 0.9 | I37: =VLOOKUP(C37,Attendance!D24:H44,5, FALSE) -> 1 | J37: =VLOOKUP(C37,Attendance!D24:K44,6, FALSE) -> 0 | K37: =VLOOKUP(C37,Attendance!D24:K44,7, FALSE) -> 1 | L37: =VLOOKUP(C37,Attendance!D24:K44,8, FALSE) -> 18 | M37: =IF(H37>65%, ">65%~<=100%", IF(H37>50%, ">50%~<=65%", IF(H37>10%, ">10%~<=50%", "<=10%"))) -> >65%~<=100% | N37: =IF(AND(H37>65%, H37<=1), "Good", IF(AND(H37>50%, H37<=65%), "Fair", IF(AND(H37>10%, H37<=50%), "Poor", IF(H37<=10%, "Critical", "Out of range")))) -> Good | AC37: =IF(COUNT(P37:Z37)=0,"",ROUND(AVERAGE(P37:Z37),2)) | AD37: =IF(AC37="","",IF(AC37>=4.2,"High Ready (4.2–5.0)",IF(AC37>=3.5,"Ready (3.5–4.1)","Developing (≤3.4)")))
B38: 13 | C38: Hsu Myat Htet | D38: Group2 | E38: =VLOOKUP(C38,Attendance!D25:M45,10, FALSE) -> N5 | F38: Offshore Development Department -1 | G38: MARK/SMART | H38: =VLOOKUP(C38,Attendance!D25:F45,3, FALSE) -> 1 | I38: =VLOOKUP(C38,Attendance!D25:H45,5, FALSE) -> 0 | J38: =VLOOKUP(C38,Attendance!D25:K45,6, FALSE) -> 0 | K38: =VLOOKUP(C38,Attendance!D25:K45,7, FALSE) -> 0 | L38: =VLOOKUP(C38,Attendance!D25:K45,8, FALSE) -> 20 | M38: =IF(H38>65%, ">65%~<=100%", IF(H38>50%, ">50%~<=65%", IF(H38>10%, ">10%~<=50%", "<=10%"))) -> >65%~<=100% | N38: =IF(AND(H38>65%, H38<=1), "Good", IF(AND(H38>50%, H38<=65%), "Fair", IF(AND(H38>10%, H38<=50%), "Poor", IF(H38<=10%, "Critical", "Out of range")))) -> Good | AC38: =IF(COUNT(P38:Z38)=0,"",ROUND(AVERAGE(P38:Z38),2)) | AD38: =IF(AC38="","",IF(AC38>=4.2,"High Ready (4.2–5.0)",IF(AC38>=3.5,"Ready (3.5–4.1)","Developing (≤3.4)")))
B39: 14 | C39: Zarli Linn Htet | D39: Group2 | E39: =VLOOKUP(C39,Attendance!D26:M46,10, FALSE) -> N5 | F39: Offshore Development Department -1 | G39: DBP | H39: =VLOOKUP(C39,Attendance!D26:F46,3, FALSE) -> 0.8 | I39: =VLOOKUP(C39,Attendance!D26:H46,5, FALSE) -> 2 | J39: =VLOOKUP(C39,Attendance!D26:K46,6, FALSE) -> 0 | K39: =VLOOKUP(C39,Attendance!D26:K46,7, FALSE) -> 2 | L39: =VLOOKUP(C39,Attendance!D26:K46,8, FALSE) -> 16 | M39: =IF(H39>65%, ">65%~<=100%", IF(H39>50%, ">50%~<=65%", IF(H39>10%, ">10%~<=50%", "<=10%"))) -> >65%~<=100% | N39: =IF(AND(H39>65%, H39<=1), "Good", IF(AND(H39>50%, H39<=65%), "Fair", IF(AND(H39>10%, H39<=50%), "Poor", IF(H39<=10%, "Critical", "Out of range")))) -> Good | AC39: =IF(COUNT(P39:Z39)=0,"",ROUND(AVERAGE(P39:Z39),2)) | AD39: =IF(AC39="","",IF(AC39>=4.2,"High Ready (4.2–5.0)",IF(AC39>=3.5,"Ready (3.5–4.1)","Developing (≤3.4)")))
B40: 15 | C40: Hnin Pwint Phyu | D40: Group2 | E40: =VLOOKUP(C40,Attendance!D27:M47,10, FALSE) -> N5 | F40: Offshore Development Department -1 | G40: Cst_Navi, BT18 | H40: =VLOOKUP(C40,Attendance!D27:F47,3, FALSE) -> 0.95 | I40: =VLOOKUP(C40,Attendance!D27:H47,5, FALSE) -> 1 | J40: =VLOOKUP(C40,Attendance!D27:K47,6, FALSE) -> 0 | K40: =VLOOKUP(C40,Attendance!D27:K47,7, FALSE) -> 0 | L40: =VLOOKUP(C40,Attendance!D27:K47,8, FALSE) -> 19 | M40: =IF(H40>65%, ">65%~<=100%", IF(H40>50%, ">50%~<=65%", IF(H40>10%, ">10%~<=50%", "<=10%"))) -> >65%~<=100% | N40: =IF(AND(H40>65%, H40<=1), "Good", IF(AND(H40>50%, H40<=65%), "Fair", IF(AND(H40>10%, H40<=50%), "Poor", IF(H40<=10%, "Critical", "Out of range")))) -> Good | P40: 3 | Q40: 3 | R40: 3 | S40: 3 | T40: 3 | U40: 3 | V40: 4 | W40: 3 | X40: 3 | Y40: 2 | Z40: 3 | AA40: 3 | AC40: =IF(COUNT(P40:Z40)=0,"",ROUND(AVERAGE(P40:Z40),2)) -> 3 | AD40: =IF(AC40="","",IF(AC40>=4.2,"High Ready (4.2–5.0)",IF(AC40>=3.5,"Ready (3.5–4.1)","Developing (≤3.4)"))) -> Developing (≤3.4)
B41: 16 | C41: Thazin San | D41: Group2 | E41: =VLOOKUP(C41,Attendance!D28:M48,10, FALSE) -> N4 | F41: Offshore Development Department -2 | G41: FAIMS-IT | H41: =VLOOKUP(C41,Attendance!D28:F48,3, FALSE) -> 0.9 | I41: =VLOOKUP(C41,Attendance!D28:H48,5, FALSE) -> 1 | J41: =VLOOKUP(C41,Attendance!D28:K48,6, FALSE) -> 1 | K41: =VLOOKUP(C41,Attendance!D28:K48,7, FALSE) -> 1 | L41: =VLOOKUP(C41,Attendance!D28:K48,8, FALSE) -> 17 | M41: =IF(H41>65%, ">65%~<=100%", IF(H41>50%, ">50%~<=65%", IF(H41>10%, ">10%~<=50%", "<=10%"))) -> >65%~<=100% | N41: =IF(AND(H41>65%, H41<=1), "Good", IF(AND(H41>50%, H41<=65%), "Fair", IF(AND(H41>10%, H41<=50%), "Poor", IF(H41<=10%, "Critical", "Out of range")))) -> Good | AC41: =IF(COUNT(P41:Z41)=0,"",ROUND(AVERAGE(P41:Z41),2)) | AD41: =IF(AC41="","",IF(AC41>=4.2,"High Ready (4.2–5.0)",IF(AC41>=3.5,"Ready (3.5–4.1)","Developing (≤3.4)")))
B42: 17 | C42: Thet Zin Aye | D42: Group2 | E42: =VLOOKUP(C42,Attendance!D29:M49,10, FALSE) -> N4 | F42: Offshore Development Department -2 | G42: FAIMS-IT | H42: =VLOOKUP(C42,Attendance!D29:F49,3, FALSE) -> 0.85 | I42: =VLOOKUP(C42,Attendance!D29:H49,5, FALSE) -> 3 | J42: =VLOOKUP(C42,Attendance!D29:K49,6, FALSE) -> 0 | K42: =VLOOKUP(C42,Attendance!D29:K49,7, FALSE) -> 0 | L42: =VLOOKUP(C42,Attendance!D29:K49,8, FALSE) -> 17 | M42: =IF(H42>65%, ">65%~<=100%", IF(H42>50%, ">50%~<=65%", IF(H42>10%, ">10%~<=50%", "<=10%"))) -> >65%~<=100% | N42: =IF(AND(H42>65%, H42<=1), "Good", IF(AND(H42>50%, H42<=65%), "Fair", IF(AND(H42>10%, H42<=50%), "Poor", IF(H42<=10%, "Critical", "Out of range")))) -> Good | AC42: =IF(COUNT(P42:Z42)=0,"",ROUND(AVERAGE(P42:Z42),2)) | AD42: =IF(AC42="","",IF(AC42>=4.2,"High Ready (4.2–5.0)",IF(AC42>=3.5,"Ready (3.5–4.1)","Developing (≤3.4)")))
B43: 18 | C43: Thinzar Aung | D43: Group2 | E43: =VLOOKUP(C43,Attendance!D30:M50,10, FALSE) -> N4 | F43: Offshore Development Department -2 | G43: WB4 | H43: =VLOOKUP(C43,Attendance!D30:F50,3, FALSE) -> 0.85 | I43: =VLOOKUP(C43,Attendance!D30:H50,5, FALSE) -> 1 | J43: =VLOOKUP(C43,Attendance!D30:K50,6, FALSE) -> 0 | K43: =VLOOKUP(C43,Attendance!D30:K50,7, FALSE) -> 2 | L43: =VLOOKUP(C43,Attendance!D30:K50,8, FALSE) -> 17 | M43: =IF(H43>65%, ">65%~<=100%", IF(H43>50%, ">50%~<=65%", IF(H43>10%, ">10%~<=50%", "<=10%"))) -> >65%~<=100% | N43: =IF(AND(H43>65%, H43<=1), "Good", IF(AND(H43>50%, H43<=65%), "Fair", IF(AND(H43>10%, H43<=50%), "Poor", IF(H43<=10%, "Critical", "Out of range")))) -> Good | AC43: =IF(COUNT(P43:Z43)=0,"",ROUND(AVERAGE(P43:Z43),2)) | AD43: =IF(AC43="","",IF(AC43>=4.2,"High Ready (4.2–5.0)",IF(AC43>=3.5,"Ready (3.5–4.1)","Developing (≤3.4)")))
...

Sheet CourseDetail
B2: Business Conversation and Communication Batch-3 N2-N3 Level 8 students Sat 19:30-20:30 (MST) ,Sun 19:00-20:30 (MST) (2hrs per week) (Total: 20 hrs course)
B3: Sr. | C3: Date | D3: Sensei | E3: Topic (Japanese)
B4: 1 | C4: Dec 27(Sat) | D4: Phyu Sin | E4: 自己紹介＋あいさつ
B5: 2 | C5: Dec 28(Sun) | D5: Yadana | E5: ロールプレイ、マナー
B6: 3 | C6: Jan 10(Sat) | D6: Phyu Sin | E6: わからない日本語を聞く＋表現・やり方を聞く
B7: 4 | C7: Jan 11(Sun) | D7: Yadana | E7: ロールプレイ、マナー
B8: 5 | C8: Jan 17(Sat) | D8: Phyu Sin | E8: 依頼＋お詫び
B9: 6 | C9: Jan 18(Sun) | D9: Yadana | E9: ロールプレイ、マナー
B10: 7 | C10: Jan 24(Sat) | D10: Phyu Sin | E10: 断り
B11: 8 | C11: Jan 25(Sun) | D11: Yadana | E11: ロールプレイ、マナー
B12: 9 | C12: Jan 31(Sat) | D12: Phyu Sin | E12: 敬語
B13: 10 | C13: Feb 1(Sun) | D13: Yadana | E13: ロールプレイ、マナー
B14: 11 | C14: Feb 7(Sat) | D14: Phyu Sin | E14: 連絡
B15: 12 | C15: Feb 8(Sun) | D15: Yadana | E15: ロールプレイ、マナー
... B23: 20 | C23: Mar 8(Sun) | D23: Yadana | E23: 最終発表 II
C24: Total: 20 Days

Sheet Attendance
B2: [Attendance Record] Batch3-Business Japanese Speaking Class
B3: Course No. 4. Business Japanese Speaking Class-30 Hours Couse (Mosarkay Japanese Language Center)
B4: 30 Hours Course Duration | E4: JLPT | F4: Sessions | H4: Attendance | I4: No. of | M4: Start Date : | N4: 46018
E5: Level | F5: Total | G5: Completed | H5: % | I5: Members | M5: End Date : | N5: 46089
B6: 28th Jan ~ 15th Mar 2026 ( 3 Hours per Session) | E6: N2-N3 | F6: =COUNTA(O11:AH11) -> 20 | G6: =COUNTA(O13:AJ13) -> 20 | H6: =AVERAGE(G13:G21) -> 0.83888889 | I6: =COUNTA(D13:D21) -> 9
E7: N4-N5 | H7: =AVERAGE(G23:G33) -> 0.87727273 | I7: =COUNTA(D23:D33) -> 11
H8: Total | I8: =SUM(I6:I7) -> 20
AE9: やすみ | AI9: Replacement
B10: Sr. | D10: Name | E10: Group | F10: % Total Attendance | G10: % Completed Attendance | H10: Leave Days | I10: Late Days | J10: Absent Days | K10: Attendance Days | L10: JLPT/NAT Level | N10: Target Certified Level Apr/Jul 2026 | O10: Day1 | P10: Day2 | Q10: Day3 | R10: Day4 | S10: Day5 | T10: Day6 | U10: Day7 | V10: Day8 | W10: Day9 | X10: Day10 | Y10: Day11 | Z10: Day12 | AA10: Day13 | AB10: Day14 | AC10: Day15 | AD10: Day16 | AE10: Day17 | AF10: Day18 | AG10: Day19 | AH10: Day20 | AI10: Day21 | AJ10: Day22
L11: Certified | M11: Study Level | O11: Dec 27 (Sat) | P11: Dec 28(Sun) | Q11: Jan 10(Sat) | R11: Jan 11(Sun) | S11: Jan 17(Sat) | T11: Jan 18(Sun) | U11: Jan 24(Sat) | V11: Jan 25(Sun) | W11: Jan 31(Sat) | X11: Feb 1(Sun) | Y11: Feb 7(Sat) | Z11: Feb 8(Sun) | AA11: Feb 14(Sat) | AB11: Feb 15(Sun) | AC11: Feb 21(Sat) | AD11: Feb 22(Sun) | AE11: Feb 28(Sat) | AF11: Mar 1(Sun) | AG11: Mar 7(Sat) | AH11: Mar 8(Sun) | AI11: Mar 14(Sat) | AJ11: Mar 15(Sun)
B12: Group1: N2-N3 Level | E12: https://teams.microsoft.com/l/meetup-join/19%3ameeting_ZmFiNmUwOGYtYzY0OC00NjMzLWFlYTctM2JhYjAxNGE4ZjU0%40thread.v2/0?context=%7b%22Tid%22%3a%22a3942a03-8939-492f-8762-ce992d7ab843%22%2c%22Oid%22%3a%22d35173b7-d170-493e-b41d-6bb910d76ef6%22%7d
B13: 1 | C13: Batch2 | D13: Yin Pa Pa | E13: Group1 | F13: =IF($F$6>0,(K13+I13)/$F$6,0) -> 1 | G13: =IF($G$6>0,(K13+I13)/$G$6,0) -> 1 | H13: =COUNTIF(O13:AJ13,"L") -> 0 | I13: =COUNTIF(O13:AJ13,"Late") -> 0 | J13: =COUNTIF(O13:AJ13,"Absent") -> 0 | K13: =COUNTIF(O13:AJ13,"A") -> 20 | L13: JLPT N3 | M13: N3 | O13: A | P13: A | Q13: A | R13: A | S13: A | T13: A | U13: A | V13: A | W13: A | X13: A | Y13: A | Z13: A | AA13: A | AB13: A | AC13: A | AD13: A | AG13: A | AH13: A | AI13: A | AJ13: A
B14: 2 | C14: Batch2 | D14: Nyein Aye Mon | E14: Group1 | F14: =IF($F$6>0,(K14+I14)/$F$6,0) -> 0.8 | G14: =IF($G$6>0,(K14+I14)/$G$6,0) -> 0.8 | H14: =COUNTIF(O14:AJ14,"L") -> 4 | I14: =COUNTIF(O14:AJ14,"Late") -> 0 | J14: =COUNTIF(O14:AJ14,"Absent") -> 0 | K14: =COUNTIF(O14:AJ14,"A") -> 16 | L14: JLPT N4 | M14: N3 | N14: N3 | O14: A | P14: A | Q14: A | R14: A | S14: A | T14: L | U14: A | V14: A | W14: A | X14: A | Y14: A | Z14: A | AA14: L | AB14: L | AC14: L | AD14: A | AG14: A | AH14: A | AI14: A | AJ14: A
B15: 3 | C15: Batch1 | D15: Nwe Oo Mon | E15: Group1 | F15: =IF($F$6>0,(K15+I15)/$F$6,0) -> 0.95 | G15: =IF($G$6>0,(K15+I15)/$G$6,0) -> 0.95 | H15: =COUNTIF(O15:AJ15,"L") -> 1 | I15: =COUNTIF(O15:AJ15,"Late") -> 0 | J15: =COUNTIF(O15:AJ15,"Absent") -> 0 | K15: =COUNTIF(O15:AJ15,"A") -> 19 | L15: JLPT N2 | M15: N2 | O15: A | P15: A | Q15: A | R15: A | S15: A | T15: A | U15: A | V15: A | W15: A | X15: L | Y15: A | Z15: A | AA15: A | AB15: A | AC15: A | AD15: A | AG15: A | AH15: A | AI15: A | AJ15: A
B16: 4 | C16: Batch1 | D16: YiMon Theint | E16: Group1 | F16: =IF($F$6>0,(K16+I16)/$F$6,0) -> 0.95 | G16: =IF($G$6>0,(K16+I16)/$G$6,0) -> 0.95 | H16: =COUNTIF(O16:AJ16,"L") -> 1 | I16: =COUNTIF(O16:AJ16,"Late") -> 0 | J16: =COUNTIF(O16:AJ16,"Absent") -> 0 | K16: =COUNTIF(O16:AJ16,"A") -> 19 | L16: JLPT N4 | M16: N3 | N16: N3 | O16: A | P16: A | Q16: A | R16: A | S16: A | T16: A | U16: A | V16: A | W16: A | X16: A | Y16: A | Z16: A | AA16: A | AB16: L | AC16: A | AD16: A | AG16: A | AH16: A | AI16: A | AJ16: A
B17: 5 | D17: Htar Htar Nwe | E17: Group1 | F17: =IF($F$6>0,(K17+I17)/$F$6,0) -> 0.8 | G17: =IF($G$6>0,(K17+I17)/$G$6,0) -> 0.8 | H17: =COUNTIF(O17:AJ17,"L") -> 4 | I17: =COUNTIF(O17:AJ17,"Late") -> 0 | J17: =COUNTIF(O17:AJ17,"Absent") -> 0 | K17: =COUNTIF(O17:AJ17,"A") -> 16 | L17: JLPT N3 | M17: N3 | N17: N2 | O17: A | P17: A | Q17: A | R17: A | S17: A | T17: A | U17: A | V17: A | W17: A | X17: A | Y17: L | Z17: L | AA17: A | AB17: A | AC17: L | AD17: L | AG17: A | AH17: A | AI17: A | AJ17: A
B18: 6 | D18: Win Thiri Han | E18: Group1 | F18: =IF($F$6>0,(K18+I18)/$F$6,0) -> 0.55 | G18: =IF($G$6>0,(K18+I18)/$G$6,0) -> 0.55 | H18: =COUNTIF(O18:AJ18,"L") -> 9 | I18: =COUNTIF(O18:AJ18,"Late") -> 0 | J18: =COUNTIF(O18:AJ18,"Absent") -> 0 | K18: =COUNTIF(O18:AJ18,"A") -> 11 | L18: JLPT N3 | M18: N3 | O18: L | P18: L | Q18: A | R18: A | S18: A | T18: L | U18: A | V18: A | W18: A | X18: L | Y18: A | Z18: A | AA18: A | AB18: L | AC18: L | AD18: L | AG18: L | AH18: A | AI18: L | AJ18: A
B19: 7 | D19: May Thazin Oo-2 | E19: Group1 | F19: =IF($F$6>0,(K19+I19)/$F$6,0) -> 0.95 | G19: =IF($G$6>0,(K19+I19)/$G$6,0) -> 0.95 | H19: =COUNTIF(O19:AJ19,"L") -> 0 | I19: =COUNTIF(O19:AJ19,"Late") -> 0 | J19: =COUNTIF(O19:AJ19,"Absent") -> 1 | K19: =COUNTIF(O19:AJ19,"A") -> 19 | L19: JLPT N3 | M19: N3 | N19: N2 | O19: Absent | P19: A | Q19: A | R19: A | S19: A | T19: A | U19: A | V19: A | W19: A | X19: A | Y19: A | Z19: A | AA19: A | AB19: A | AC19: A | AD19: A | AG19: A | AH19: A | AI19: A | AJ19: A
B20: 8 | D20: Soe Nandar | E20: Group1 | F20: =IF($F$6>0,(K20+I20)/$F$6,0) -> 0.95 | G20: =IF($G$6>0,(K20+I20)/$G$6,0) -> 0.95 | H20: =COUNTIF(O20:AJ20,"L") -> 0 | I20: =COUNTIF(O20:AJ20,"Late") -> 0 | J20: =COUNTIF(O20:AJ20,"Absent") -> 1 | K20: =COUNTIF(O20:AJ20,"A") -> 19 | L20: JLPT N2 | M20: N2 | O20: Absent | P20: A | Q20: A | R20: A | S20: A | T20: A | U20: A | V20: A | W20: A | X20: A | Y20: A | Z20: A | AA20: A | AB20: A | AC20: A | AD20: A | AG20: A | AH20: A | AI20: A | AJ20: A
B21: 9 | D21: Hsu Nandar Htet | E21: Group1 | F21: =IF($F$6>0,(K21+I21)/$F$6,0) -> 0.6 | G21: =IF($G$6>0,(K21+I21)/$G$6,0) -> 0.6 | H21: =COUNTIF(O21:AJ21,"L") -> 4 | I21: =COUNTIF(O21:AJ21,"Late") -> 0 | J21: =COUNTIF(O21:AJ21,"Absent") -> 4 | K21: =COUNTIF(O21:AJ21,"A") -> 12 | L21: JLPT N3 | M21: N2 | N21: N2 | O21: A | P21: A | Q21: Absent | R21: Absent | S21: A | T21: A | U21: Absent | V21: Absent | W21: A | X21: A | Y21: A | Z21: L | AA21: A | AB21: A | AC21: L | AD21: L | AG21: A | AH21: A | AI21: A | AJ21: L
B22: Group2: N4-N5 Level | E22: https://teams.microsoft.com/l/meetup-join/19%3ameeting_ZmFiNmUwOGYtYzY0OC00NjMzLWFlYTctM2JhYjAxNGE4ZjU0%40thread.v2/0?context=%7b%22Tid%22%3a%22a3942a03-8939-492f-8762-ce992d7ab843%22%2c%22Oid%22%3a%22d35173b7-d170-493e-b41d-6bb910d76ef6%22%7d
B23: 10 | D23: Saung Thinzar Khaing | E23: Group2 | F23: =IF($F$6>0,(K23+I23)/$F$6,0) -> 0.9 | G23: =IF($G$6>0,(K23+I23)/$G$6,0) -> 0.9 | H23: =COUNTIF(O23:AJ23,"L") -> 1 | I23: =COUNTIF(O23:AJ23,"Late") -> 1 | J23: =COUNTIF(O23:AJ23,"Absent") -> 1 | K23: =COUNTIF(O23:AJ23,"A") -> 17 | M23: N5 | N23: N4 | O23: A | P23: A | Q23: Absent | R23: A | S23: A | T23: A | U23: A | V23: L | W23: A | X23: A | Y23: A | Z23: A | AA23: A | AB23: A | AC23: A | AD23: Late | AG23: A | AH23: A | AI23: A | AJ23: A
B24: 11 | C24: Batch2 | D24: Kyipyar Lwin | E24: Group2 | F24: =IF($F$6>0,(K24+I24)/$F$6,0) -> 0.95 | G24: =IF($G$6>0,(K24+I24)/$G$6,0) -> 0.95 | H24: =COUNTIF(O24:AJ24,"L") -> 1 | I24: =COUNTIF(O24:AJ24,"Late") -> 0 | J24: =COUNTIF(O24:AJ24,"Absent") -> 0 | K24: =COUNTIF(O24:AJ24,"A") -> 19 | M24: N4 | N24: N3 | O24: A | P24: A | Q24: A | R24: A | S24: A | T24: A | U24: A | V24: A | W24: A | X24: A | Y24: A | Z24: A | AA24: A | AB24: A | AC24: A | AD24: L | AG24: A | AH24: A | AI24: A | AJ24: A
B25: 12 | D25: Myo Soe Aung | E25: Group2 | F25: =IF($F$6>0,(K25+I25)/$F$6,0) -> 0.9 | G25: =IF($G$6>0,(K25+I25)/$G$6,0) -> 0.9 | H25: =COUNTIF(O25:AJ25,"L") -> 1 | I25: =COUNTIF(O25:AJ25,"Late") -> 0 | J25: =COUNTIF(O25:AJ25,"Absent") -> 1 | K25: =COUNTIF(O25:AJ25,"A") -> 18 | M25: N5 | N25: N4 | O25: A | P25: A | Q25: A | R25: Absent | S25: A | T25: A | U25: A | V25: A | W25: A | X25: A | Y25: A | Z25: A | AA25: A | AB25: L | AC25: A | AD25: A | AG25: A | AH25: A | AI25: A | AJ25: A
B26: 13 | D26: Hsu Myat Htet | E26: Group2 | F26: =IF($F$6>0,(K26+I26)/$F$6,0) -> 1 | G26: =IF($G$6>0,(K26+I26)/$G$6,0) -> 1 | H26: =COUNTIF(O26:AJ26,"L") -> 0 | I26: =COUNTIF(O26:AJ26,"Late") -> 0 | J26: =COUNTIF(O26:AJ26,"Absent") -> 0 | K26: =COUNTIF(O26:AJ26,"A") -> 20 | M26: N5 | O26: A | P26: A | Q26: A | R26: A | S26: A | T26: A | U26: A | V26: A | W26: A | X26: A | Y26: A | Z26: A | AA26: A | AB26: A | AC26: A | AD26: A | AG26: A | AH26: A | AI26: A | AJ26: A
B27: 14 | D27: Zarli Linn Htet | E27: Group2 | F27: =IF($F$6>0,(K27+I27)/$F$6,0) -> 0.8 | G27: =IF($G$6>0,(K27+I27)/$G$6,0) -> 0.8 | H27: =COUNTIF(O27:AJ27,"L") -> 2 | I27: =COUNTIF(O27:AJ27,"Late") -> 0 | J27: =COUNTIF(O27:AJ27,"Absent") -> 2 | K27: =COUNTIF(O27:AJ27,"A") -> 16 | M27: N5 | N27: N4 | O27: A | P27: A | Q27: Absent | R27: Absent | S27: A | T27: A | U27: A | V27: A | W27: A | X27: A | Y27: L | Z27: A | AA27: A | AB27: A | AC27: A | AD27: A | AG27: L | AH27: A | AI27: A | AJ27: A
B28: 15 | D28: Hnin Pwint Phyu | E28: Group2 | F28: =IF($F$6>0,(K28+I28)/$F$6,0) -> 0.95 | G28: =IF($G$6>0,(K28+I28)/$G$6,0) -> 0.95 | H28: =COUNTIF(O28:AJ28,"L") -> 1 | I28: =COUNTIF(O28:AJ28,"Late") -> 0 | J28: =COUNTIF(O28:AJ28,"Absent") -> 0 | K28: =COUNTIF(O28:AJ28,"A") -> 19 | M28: N5 | N28: N3 | O28: A | P28: A | Q28: A | R28: A | S28: A | T28: A | U28: A | V28: A | W28: A | X28: A | Y28: A | Z28: A | AA28: A | AB28: L | AC28: A | AD28: A | AG28: A | AH28: A | AI28: A | AJ28: A
B29: 16 | D29: Thazin San | E29: Group2 | F29: =IF($F$6>0,(K29+I29)/$F$6,0) -> 0.9 | G29: =IF($G$6>0,(K29+I29)/$G$6,0) -> 0.9 | H29: =COUNTIF(O29:AJ29,"L") -> 1 | I29: =COUNTIF(O29:AJ29,"Late") -> 1 | J29: =COUNTIF(O29:AJ29,"Absent") -> 1 | K29: =COUNTIF(O29:AJ29,"A") -> 17 | M29: N4 | N29: N4 | O29: A | P29: A | Q29: A | R29: Absent | S29: A | T29: A | U29: A | V29: A | W29: A | X29: A | Y29: A | Z29: A | AA29: A | AB29: A | AC29: A | AD29: Late | AG29: A | AH29: A | AI29: A | AJ29: L
B30: 17 | D30: Thet Zin Aye | E30: Group2 | F30: =IF($F$6>0,(K30+I30)/$F$6,0) -> 0.85 | G30: =IF($G$6>0,(K30+I30)/$G$6,0) -> 0.85 | H30: =COUNTIF(O30:AJ30,"L") -> 3 | I30: =COUNTIF(O30:AJ30,"Late") -> 0 | J30: =COUNTIF(O30:AJ30,"Absent") -> 0 | K30: =COUNTIF(O30:AJ30,"A") -> 17 | M30: N4 | N30: N3 | O30: A | P30: A | Q30: A | R30: A | S30: A | T30: L | U30: A | V30: A | W30: A | X30: L | Y30: A | Z30: A | AA30: A | AB30: A | AC30: A | AD30: L | AG30: A | AH30: A | AI30: A | AJ30: A
B31: 18 | D31: Thinzar Aung | E31: Group2 | F31: =IF($F$6>0,(K31+I31)/$F$6,0) -> 0.85 | G31: =IF($G$6>0,(K31+I31)/$G$6,0) -> 0.85 | H31: =COUNTIF(O31:AJ31,"L") -> 1 | I31: =COUNTIF(O31:AJ31,"Late") -> 0 | J31: =COUNTIF(O31:AJ31,"Absent") -> 2 | K31: =COUNTIF(O31:AJ31,"A") -> 17 | L31: Top J Level (A) | M31: N4 | N31: N4 | O31: Absent | P31: Absent | Q31: A | R31: A | S31: A | T31: A | U31: A | V31: A | W31: A | X31: A | Y31: A | Z31: A | AA31: A | AB31: A | AC31: A | AD31: A | AG31: A | AH31: A | AI31: L | AJ31: A
B32: 19 | D32: Su Nandar Htwe | E32: Group2 | F32: =IF($F$6>0,(K32+I32)/$F$6,0) -> 0.85 | G32: =IF($G$6>0,(K32+I32)/$G$6,0) -> 0.85 | H32: =COUNTIF(O32:AJ32,"L") -> 3 | I32: =COUNTIF(O32:AJ32,"Late") -> 0 | J32: =COUNTIF(O32:AJ32,"Absent") -> 0 | K32: =COUNTIF(O32:AJ32,"A") -> 17 | M32: N5 | N32: N4 | O32: L | P32: L | Q32: A | R32: A | S32: A | T32: A | U32: A | V32: A | W32: A | X32: A | Y32: L | Z32: A | AA32: A | AB32: A | AC32: A | AD32: A | AG32: A | AH32: A | AI32: A | AJ32: A
B33: 20 | D33: Zay Yar Hein | E33: Group2 | F33: =IF($F$6>0,(K33+I33)/$F$6,0) -> 0.7 | G33: =IF($G$6>0,(K33+I33)/$G$6,0) -> 0.7 | H33: =COUNTIF(O33:AJ33,"L") -> 3 | I33: =COUNTIF(O33:AJ33,"Late") -> 0 | J33: =COUNTIF(O33:AJ33,"Absent") -> 3 | K33: =COUNTIF(O33:AJ33,"A") -> 14 | L33: =VLOOKUP(D33,BJS!$C$12:$F$31,2, FALSE) | M33: N5 | N33: N4 | O33: A | P33: Absent | Q33: Absent | R33: Absent | S33: A | T33: A | U33: A | V33: L | W33: A | X33: L | Y33: A | Z33: A | AA33: A | AB33: L | AC33: A | AD33: A | AG33: A | AH33: A | AI33: A | AJ33: A

Sheet BJS
A2: Business Japanese Speaking (2026 January ~ March)
A3: Mosarkay Japanese Language School
B4: N2 | C4: =COUNTIFS($E$12:$E$31, B4) -> 3
B5: N3 | C5: =COUNTIFS($E$12:$E$31, B5) -> 6
B6: N4 | C6: =COUNTIFS($E$12:$E$31, B6) -> 4
B7: N5 | C7: =COUNTIFS($E$12:$E$31, B7) -> 6
B8: No Level | C8: 1
B9: Total | C9: =SUM(C4:C8) -> 20
A11: Sr | B11: Name | D11: JLPT Certified | E11: JLPT Study Level | F11: Group | G11: Curriculum and Schedule File | H11: Education | I11: Position | J11: Department | K11: Contact Email | L11: Phone Number
A12: 1 | B12: Mrs | C12: Yin Pa Pa | D12: JLPT N3 | E12: N3 | F12: Group1 | G12: Batch3 N3 N2 Level Business Japanese Curriculum.xlsx | H12: B.C.Sc (Hons:) | I12: Executive Manager | J12: Offshore Development Department-1 | K12: yinpapa@diracetechnology.com | L12: 09-256149364
A13: 2 | B13: Ms | C13: Nyein Aye Mon | D13: JLPT N4 | E13: N3 | F13: Group1 | H13: B.E (IT) | I13: Senior Project Manager | J13: Offshore Development Department-1 | K13: nyeinayemon@diracetechnology.com | L13: 09-448046585
A14: 3 | B14: Ms | C14: Nwe Oo Mon | D14: JLPT N2 | E14: N2 | F14: Group1 | H14: BA (Eng) | I14: Deputy Project Manager | J14: Offshore Development Department-2 | K14: nweoomon@diracetechnology.com | L14: 09250273083
A15: 4 | B15: Ms | C15: YiMon Theint | D15: JLPT N4 | E15: N3 | F15: Group1 | H15: MCSc (Course Work) | I15: Senior Project Lead | J15: Offshore Development Department-2 | K15: yimontheint@diracetechnology.com | L15: 09978930568
A16: 5 | B16: Mrs | C16: Htar Htar Nwe | D16: JLPT N3 | E16: N3 | F16: Group1 | H16: BA (Myanmar) | I16: Senior Software Engineer-1 | J16: Offshore Development Department-2 | K16: htarhtarnwe@diracetechnology.com | L16: 09797888423
A17: 6 | B17: Mrs | C17: Win Thiri Han | D17: JLPT N3 | E17: N3 | F17: Group1 | H17: BCSc | I17: Executive Manager | J17: Offshore Development Department-2 | K17: winthirihan@diracetechnology.com | L17: 09795262472
A18: 7 | B18: Ms | C18: May Thazin Oo-2 | D18: JLPT N3 | E18: N3 | F18: Group1 | H18: BCSc | I18: Team Leader | J18: Offshore Development Department-2 | K18: maythazinoo2@diracetechnology.com | L18: 09977377921
A19: 8 | B19: Ms | C19: Soe Nandar | D19: JLPT N2 | E19: N2 | F19: Group1 | H19: BCSc | I19: Deputy Project Manager | J19: Offshore Development Department-2 | K19: soenandar@diracetechnology.com | L19: 09778801528
A20: 9 | B20: Mrs | C20: Saung Thinzar Khaing | E20: N5 | F20: Group2 | G20: N5 N4 Level Business Japanese Curriculum.docx | H20: B.E (IT) | I20: Deputy Project Manager | J20: Offshore Development Department-1 | K20: saungthinzarkhaing@diracetechnology.com | L20: 09-799862097
A21: 10 | B21: Mrs | C21: Kyipyar Lwin | E21: N4 | F21: Group2 | H21: B.C.Sc | I21: Project Lead | J21: Offshore Development Department-1 | K21: kyipyarlwin@diracetechnology.com | L21: 09-453221548
A22: 11 | B22: Mr | C22: Myo Soe Aung | E22: N5 | F22: Group2 | H22: B.C.Sc | I22: Senior Software Engineer-1 | J22: Offshore Development Department-1 | K22: myosoeaung@diracetechnology.com | L22: 09-691896138 09-786307103
A23: 12 | B23: Ms | C23: Hsu Myat Htet | E23: N5 | F23: Group2 | H23: B.C.Sc | I23: Senior Software Engineer-1 | J23: Offshore Development Department-1 | K23: hsumyathtet@diracetechnology.com | L23: 09-950212992
A24: 13 | B24: Ms | C24: Zarli Linn Htet | E24: N5 | F24: Group2 | H24: B.C.Sc | I24: Senior Software Engineer-1 | J24: Offshore Development Department-1 | K24: zarlilinnhtet@diracetechnology.com | L24: 09-978700614
A25: 14 | B25: Ms | C25: Hnin Pwint Phyu | E25: N5 | F25: Group2 | H25: B.C.Sc (Hons:) | I25: Senior Software Engineer-2 | J25: Offshore Development Department-1 | K25: hninpwintphyu@diracetechnology.com | L25: 09- 423667396
A26: 15 | B26: Ms | C26: Hsu Nandar Htet | D26: JLPT N3 | E26: N2 | F26: Group1 | H26: B.C.Sc | I26: Deputy Project Manager | J26: Offshore Development Department-1 | K26: hsunandarhtet@diracetechnology.com | L26: 09-791692808
A27: 16 | B27: Ms | C27: Thazin San | E27: N4 | F27: Group2 | H27: BCSc | I27: Deputy Project Manager | J27: Offshore Development Department-2 | K27: thazinsan@diracetechnology.com | L27: 09254323051
A28: 17 | B28: Ms | C28: Thet Zin Aye | E28: N4 | F28: Group2 | H28: BCSc | I28: Senior Software Engineer-2 | J28: Offshore Development Department-2 | K28: thetzinaye@diracetechnology.com | L28: 09458239273
A29: 18 | B29: Mrs | C29: Thinzar Aung | D29: Top J Level (A) | E29: N4 | F29: Group2 | H29: MCSc | I29: Senior Project Manager | J29: Offshore Development Department-2 | K29: thinzaraung@diracetechnology.com | L29: 09792733589
A30: 19 | B30: Ms | C30: Su Nandar Htwe | E30: N5 | F30: Group2 | H30: BCSc (Hons) | I30: Project Manager | J30: Offshore Development Department-2 | K30: sunandarhtwe@diracetechnology.com | L30: 09799788223/ 095156462
A31: 20 | B31: Mr | C31: Zay Yar Hein | F31: Group2 | H31: BA (Myanmar) | I31: Project Manager | J31: Offshore Development Department-2 | K31: zayyarhein@diracetechnology.com | L31: 09420198016/ 09977803756
